<?xml version="1.0"?>        <!-- to recognize the file as xml file, URDF uses metric system -->
<robot name="my_robot">        <!-- robot tag -->

    <material name="blue">
        <color rgba="0 0 0.5 1" />
    </material>

    <material name="grey">
        <color rgba="0.5 0.5 0.5 1" />
    </material>

    <link name="base_link">    <!-- base link tag -->
        <visual>
            <geometry>
                <box size="0.6 0.4 0.2" />     <!-- box tag to make a box of dimensions 0.6 0.4 0.2 -->
            </geometry>
            <origin xyz="0 0 0.1" rpy="0 0 0" />     <!-- origin of translation and rotation -->
            <material name="blue" />
        </visual>
    </link>

    <link name="right_wheel_link">
        <visual>
            <geometry>
                <cylinder radius="0.1" length="0.05" />
            </geometry>
            <origin xyz="0 0 0" rpy="0 0 0" />
            <material name="grey" />
        </visual>
    </link>

    <joint name="base_right_wheel_joint" type="continuous">
        <parent link="base_link" />
        <child link="right_wheel_link" />
        <origin xyz="-0.15 -0.225 0" rpy="-1.57 0 0" />
        <axis xyz="0 0 1" />
    </joint>



</robot>    


   

